Not Found: /
Not Found: /favicon.ico
Not Found: /backend/
Not Found: /favicon.ico
Internal Server Error: /admin/login/
Traceback (most recent call last):
  File "D:\i-stech\workspace\his-pacs-integration-api\env\Lib\site-packages\django\core\handlers\exception.py", line 47, in inner
    response = get_response(request)
               ^^^^^^^^^^^^^^^^^^^^^
  File "D:\i-stech\workspace\his-pacs-integration-api\env\Lib\site-packages\django\core\handlers\base.py", line 181, in _get_response
    response = wrapped_callback(request, *callback_args, **callback_kwargs)
               ^^^^^^^^^^^^^^^^^^^^^^^^^^^^^^^^^^^^^^^^^^^^^^^^^^^^^^^^^^^^
  File "D:\i-stech\workspace\his-pacs-integration-api\env\Lib\site-packages\django\views\decorators\cache.py", line 44, in _wrapped_view_func
    response = view_func(request, *args, **kwargs)
               ^^^^^^^^^^^^^^^^^^^^^^^^^^^^^^^^^^^
  File "D:\i-stech\workspace\his-pacs-integration-api\env\Lib\site-packages\django\contrib\admin\sites.py", line 414, in login
    return LoginView.as_view(**defaults)(request)
           ^^^^^^^^^^^^^^^^^^^^^^^^^^^^^^^^^^^^^^
  File "D:\i-stech\workspace\his-pacs-integration-api\env\Lib\site-packages\django\views\generic\base.py", line 70, in view
    return self.dispatch(request, *args, **kwargs)
           ^^^^^^^^^^^^^^^^^^^^^^^^^^^^^^^^^^^^^^^
  File "D:\i-stech\workspace\his-pacs-integration-api\env\Lib\site-packages\django\utils\decorators.py", line 43, in _wrapper
    return bound_method(*args, **kwargs)
           ^^^^^^^^^^^^^^^^^^^^^^^^^^^^^
  File "D:\i-stech\workspace\his-pacs-integration-api\env\Lib\site-packages\django\views\decorators\debug.py", line 89, in sensitive_post_parameters_wrapper
    return view(request, *args, **kwargs)
           ^^^^^^^^^^^^^^^^^^^^^^^^^^^^^^
  File "D:\i-stech\workspace\his-pacs-integration-api\env\Lib\site-packages\django\utils\decorators.py", line 43, in _wrapper
    return bound_method(*args, **kwargs)
           ^^^^^^^^^^^^^^^^^^^^^^^^^^^^^
  File "D:\i-stech\workspace\his-pacs-integration-api\env\Lib\site-packages\django\utils\decorators.py", line 130, in _wrapped_view
    response = view_func(request, *args, **kwargs)
               ^^^^^^^^^^^^^^^^^^^^^^^^^^^^^^^^^^^
  File "D:\i-stech\workspace\his-pacs-integration-api\env\Lib\site-packages\django\utils\decorators.py", line 43, in _wrapper
    return bound_method(*args, **kwargs)
           ^^^^^^^^^^^^^^^^^^^^^^^^^^^^^
  File "D:\i-stech\workspace\his-pacs-integration-api\env\Lib\site-packages\django\views\decorators\cache.py", line 44, in _wrapped_view_func
    response = view_func(request, *args, **kwargs)
               ^^^^^^^^^^^^^^^^^^^^^^^^^^^^^^^^^^^
  File "D:\i-stech\workspace\his-pacs-integration-api\env\Lib\site-packages\django\contrib\auth\views.py", line 63, in dispatch
    return super().dispatch(request, *args, **kwargs)
           ^^^^^^^^^^^^^^^^^^^^^^^^^^^^^^^^^^^^^^^^^^
  File "D:\i-stech\workspace\his-pacs-integration-api\env\Lib\site-packages\django\views\generic\base.py", line 98, in dispatch
    return handler(request, *args, **kwargs)
           ^^^^^^^^^^^^^^^^^^^^^^^^^^^^^^^^^
  File "D:\i-stech\workspace\his-pacs-integration-api\env\Lib\site-packages\django\views\generic\edit.py", line 141, in post
    if form.is_valid():
       ^^^^^^^^^^^^^^^
  File "D:\i-stech\workspace\his-pacs-integration-api\env\Lib\site-packages\django\forms\forms.py", line 175, in is_valid
    return self.is_bound and not self.errors
                                 ^^^^^^^^^^^
  File "D:\i-stech\workspace\his-pacs-integration-api\env\Lib\site-packages\django\forms\forms.py", line 170, in errors
    self.full_clean()
  File "D:\i-stech\workspace\his-pacs-integration-api\env\Lib\site-packages\django\forms\forms.py", line 373, in full_clean
    self._clean_form()
  File "D:\i-stech\workspace\his-pacs-integration-api\env\Lib\site-packages\django\forms\forms.py", line 400, in _clean_form
    cleaned_data = self.clean()
                   ^^^^^^^^^^^^
  File "D:\i-stech\workspace\his-pacs-integration-api\env\Lib\site-packages\django\contrib\auth\forms.py", line 202, in clean
    self.user_cache = authenticate(self.request, username=username, password=password)
                      ^^^^^^^^^^^^^^^^^^^^^^^^^^^^^^^^^^^^^^^^^^^^^^^^^^^^^^^^^^^^^^^^
  File "D:\i-stech\workspace\his-pacs-integration-api\env\Lib\site-packages\django\views\decorators\debug.py", line 42, in sensitive_variables_wrapper
    return func(*func_args, **func_kwargs)
           ^^^^^^^^^^^^^^^^^^^^^^^^^^^^^^^
  File "D:\i-stech\workspace\his-pacs-integration-api\env\Lib\site-packages\django\contrib\auth\__init__.py", line 76, in authenticate
    user = backend.authenticate(request, **credentials)
           ^^^^^^^^^^^^^^^^^^^^^^^^^^^^^^^^^^^^^^^^^^^^
  File "D:\i-stech\workspace\his-pacs-integration-api\env\Lib\site-packages\django\contrib\auth\backends.py", line 42, in authenticate
    user = UserModel._default_manager.get_by_natural_key(username)
           ^^^^^^^^^^^^^^^^^^^^^^^^^^^^^^^^^^^^^^^^^^^^^
AttributeError: 'ObjectManager' object has no attribute 'get_by_natural_key'
Forbidden: /api/orders
Forbidden: /api/orders
Forbidden: /api/orders
Forbidden: /api/orders
Forbidden: /api/orders
Forbidden: /api/orders
Forbidden: /api/orders
Internal Server Error: /api/orders
Traceback (most recent call last):
  File "d:\i-stech\workspace\his-pacs-integration-api\env\Lib\site-packages\rest_framework\views.py", line 506, in dispatch
    response = handler(request, *args, **kwargs)
               ^^^^^^^^^^^^^^^^^^^^^^^^^^^^^^^^^
  File "D:\i-stech\workspace\his-pacs-integration-api\backend\apps\account\views.py", line 919, in post
    if not has_permission and not user.is_superuser:
           ^^^^^^^^^^^^^^
  File "c:\Users\Admin\.vscode\extensions\ms-python.debugpy-2024.8.0-win32-x64\bundled\libs\debugpy\_vendored\pydevd\_pydevd_bundle\pydevd_trace_dispatch_regular.py", line 203, in trace_dispatch
    py_db.enable_tracing(thread_trace_func)
  File "c:\Users\Admin\.vscode\extensions\ms-python.debugpy-2024.8.0-win32-x64\bundled\libs\debugpy\_vendored\pydevd\pydevd.py", line 1107, in enable_tracing
    pydevd_tracing.SetTrace(thread_trace_func)
  File "c:\Users\Admin\.vscode\extensions\ms-python.debugpy-2024.8.0-win32-x64\bundled\libs\debugpy\_vendored\pydevd\pydevd_tracing.py", line 87, in SetTrace
    if set_trace_to_threads(tracing_func, thread_idents=[thread.get_ident()], create_dummy_thread=False) == 0:
       ^^^^^^^^^^^^^^^^^^^^^^^^^^^^^^^^^^^^^^^^^^^^^^^^^^^^^^^^^^^^^^^^^^^^^^^^^^^^^^^^^^^^^^^^^^^^^^^^^
  File "c:\Users\Admin\.vscode\extensions\ms-python.debugpy-2024.8.0-win32-x64\bundled\libs\debugpy\_vendored\pydevd\pydevd_tracing.py", line 354, in set_trace_to_threads
    start_new_thread(increase_tracing_count, ())
RuntimeError: can't create new thread at interpreter shutdown

During handling of the above exception, another exception occurred:

Traceback (most recent call last):
  File "d:\i-stech\workspace\his-pacs-integration-api\env\Lib\site-packages\rest_framework\request.py", line 416, in __getattr__
    return getattr(self._request, attr)
           ^^^^^^^^^^^^^^^^^^^^^^^^^^^^
AttributeError: 'WSGIRequest' object has no attribute 'accepted_renderer'

During handling of the above exception, another exception occurred:

Traceback (most recent call last):
  File "d:\i-stech\workspace\his-pacs-integration-api\env\Lib\site-packages\django\core\handlers\exception.py", line 47, in inner
    response = get_response(request)
               ^^^^^^^^^^^^^^^^^^^^^
  File "d:\i-stech\workspace\his-pacs-integration-api\env\Lib\site-packages\django\core\handlers\base.py", line 181, in _get_response
    response = wrapped_callback(request, *callback_args, **callback_kwargs)
               ^^^^^^^^^^^^^^^^^^^^^^^^^^^^^^^^^^^^^^^^^^^^^^^^^^^^^^^^^^^^
  File "d:\i-stech\workspace\his-pacs-integration-api\env\Lib\site-packages\django\views\decorators\csrf.py", line 54, in wrapped_view
    return view_func(*args, **kwargs)
           ^^^^^^^^^^^^^^^^^^^^^^^^^^
  File "d:\i-stech\workspace\his-pacs-integration-api\env\Lib\site-packages\django\views\generic\base.py", line 70, in view
    return self.dispatch(request, *args, **kwargs)
           ^^^^^^^^^^^^^^^^^^^^^^^^^^^^^^^^^^^^^^^
  File "D:\i-stech\workspace\his-pacs-integration-api\backend\third_parties\contribution\api_view.py", line 65, in dispatch
    return super().dispatch(*args, **kwargs)
           ^^^^^^^^^^^^^^^^^^^^^^^^^^^^^^^^^
  File "d:\i-stech\workspace\his-pacs-integration-api\env\Lib\site-packages\rest_framework\views.py", line 509, in dispatch
    response = self.handle_exception(exc)
               ^^^^^^^^^^^^^^^^^^^^^^^^^^
  File "d:\i-stech\workspace\his-pacs-integration-api\env\Lib\site-packages\rest_framework\views.py", line 469, in handle_exception
    self.raise_uncaught_exception(exc)
  File "d:\i-stech\workspace\his-pacs-integration-api\env\Lib\site-packages\rest_framework\views.py", line 477, in raise_uncaught_exception
    renderer_format = getattr(request.accepted_renderer, 'format')
                              ^^^^^^^^^^^^^^^^^^^^^^^^^
  File "d:\i-stech\workspace\his-pacs-integration-api\env\Lib\site-packages\rest_framework\request.py", line 418, in __getattr__
    return self.__getattribute__(attr)
           ^^^^^^^^^^^^^^^^^^^^^^^^^^^
AttributeError: 'Request' object has no attribute 'accepted_renderer'
Forbidden: /api/orders
Forbidden: /api/orders
Forbidden: /api/orders
Bad Request: /api/orders
Forbidden: /api/orders
Forbidden: /api/orders
Forbidden: /api/orders
Bad Request: /api/orders
Bad Request: /api/orders
Bad Request: /api/orders
Bad Request: /api/orders
Bad Request: /api/orders
Bad Request: /api/orders
Bad Request: /api/orders
Bad Request: /api/orders
Bad Request: /api/orders
Bad Request: /api/orders
Bad Request: /api/orders
strptime() argument 1 must be str, not datetime.datetime
Traceback (most recent call last):
  File "D:\i-stech\workspace\his-pacs-integration-api\backend\apps\account\views.py", line 970, in post
    order_time=convert_str_to_datetime(data['order_time']),
               ^^^^^^^^^^^^^^^^^^^^^^^^^^^^^^^^^^^^^^^^^^^
  File "D:\i-stech\workspace\his-pacs-integration-api\backend\apps\account\utils.py", line 72, in convert_str_to_datetime
    return datetime.datetime.strptime(date_str, format_str)
           ^^^^^^^^^^^^^^^^^^^^^^^^^^^^^^^^^^^^^^^^^^^^^^^^
TypeError: strptime() argument 1 must be str, not datetime.datetime
strptime() argument 1 must be str, not datetime.datetime
Traceback (most recent call last):
  File "D:\i-stech\workspace\his-pacs-integration-api\backend\apps\account\views.py", line 970, in post
    order_time=convert_str_to_datetime(data['order_time']),
               ^^^^^^^^^^^^^^^^^^^^^^^^^^^^^^^^^^^^^^^^^^^
  File "D:\i-stech\workspace\his-pacs-integration-api\backend\apps\account\utils.py", line 72, in convert_str_to_datetime
    return datetime.datetime.strptime(date_str, format_str)
           ^^^^^^^^^^^^^^^^^^^^^^^^^^^^^^^^^^^^^^^^^^^^^^^^
TypeError: strptime() argument 1 must be str, not datetime.datetime
strptime() argument 1 must be str, not datetime.datetime
Traceback (most recent call last):
  File "D:\i-stech\workspace\his-pacs-integration-api\backend\apps\account\views.py", line 970, in post
    order_time=convert_str_to_datetime(data['order_time']),
               ^^^^^^^^^^^^^^^^^^^^^^^^^^^^^^^^^^^^^^^^^^^
  File "D:\i-stech\workspace\his-pacs-integration-api\backend\apps\account\utils.py", line 72, in convert_str_to_datetime
    return datetime.datetime.strptime(date_str, format_str)
           ^^^^^^^^^^^^^^^^^^^^^^^^^^^^^^^^^^^^^^^^^^^^^^^^
TypeError: strptime() argument 1 must be str, not datetime.datetime
strptime() argument 1 must be str, not datetime.datetime
Traceback (most recent call last):
  File "D:\i-stech\workspace\his-pacs-integration-api\backend\apps\account\views.py", line 970, in post
    order_time=convert_str_to_datetime(data['order_time']),
               ^^^^^^^^^^^^^^^^^^^^^^^^^^^^^^^^^^^^^^^^^^^
  File "D:\i-stech\workspace\his-pacs-integration-api\backend\apps\account\utils.py", line 72, in convert_str_to_datetime
    return datetime.datetime.strptime(date_str, format_str)
           ^^^^^^^^^^^^^^^^^^^^^^^^^^^^^^^^^^^^^^^^^^^^^^^^
TypeError: strptime() argument 1 must be str, not datetime.datetime
strptime() argument 1 must be str, not datetime.datetime
Traceback (most recent call last):
  File "D:\i-stech\workspace\his-pacs-integration-api\backend\apps\account\views.py", line 970, in post
    order_time=convert_str_to_datetime(data['order_time']),
               ^^^^^^^^^^^^^^^^^^^^^^^^^^^^^^^^^^^^^^^^^^^
  File "D:\i-stech\workspace\his-pacs-integration-api\backend\apps\account\utils.py", line 72, in convert_str_to_datetime
    return datetime.datetime.strptime(date_str, format_str)
           ^^^^^^^^^^^^^^^^^^^^^^^^^^^^^^^^^^^^^^^^^^^^^^^^
TypeError: strptime() argument 1 must be str, not datetime.datetime
